2025-06-18 15:23:50,434 - main_sequential - INFO - --- CAPTURING ALL OUTPUT for req_id ea52aa6a to: full_request_logs/req_full_output_20250618_152350_433842_ea52aa6a.log ---
2025-06-18 15:23:50,435 - api.routes.agent_sequential - INFO - Initializing AgentManager singleton.
2025-06-18 15:23:50,436 - api.routes.agent_sequential - INFO - Console: Received query in agent.py endpoint: Which category had the lowest average sales?
2025-06-18 15:23:50,437 - core.agent_manager_sequential - INFO - AgentManager.process_query received query: 'Which category had the lowest average sales?'
2025-06-18 15:23:50,437 - core.agent_manager_sequential - INFO - --- XIYAN-SQL ORCHESTRATED WORKFLOW START ---
2025-06-18 15:23:50,528 - core.agents_sequential - INFO - METADATA_AVAILABLE is True. Registering data dictionary tools.
2025-06-18 15:23:50,551 - core.agent_manager_sequential - INFO - [Orchestrator] STAGE 1: Schema Linking
--- STDOUT/STDERR REDIRECTION ACTIVE (ReqID: ea52aa6a, Time: 2025-06-18 15:23:50.434608) ---
instantiated AgentManagerSequential object
created new sequential agents
[33mUserProxy[0m (to SchemaAnalyst):

User Question: 'Which category had the lowest average sales?'

--------------------------------------------------------------------------------
[31m
>>>>>>>> USING AUTO REPLY...[0m
2025-06-18 15:23:51,497 - httpx - INFO - HTTP Request: POST https://api.openai.com/v1/chat/completions "HTTP/1.1 200 OK"
[33mSchemaAnalyst[0m (to UserProxy):

[32m***** Suggested tool call (call_ukDRXVruqdmXOfrbmMt8h8AX): get_data_dictionary_tables *****[0m
Arguments: 
{}
[32m*******************************************************************************************[0m

--------------------------------------------------------------------------------
[35m
>>>>>>>> EXECUTING FUNCTION get_data_dictionary_tables...
Call ID: call_ukDRXVruqdmXOfrbmMt8h8AX
Input arguments: {}[0m
2025-06-18 15:23:51,502 - tools.db_tools - WARNING - METADATA SCHEMA (DB_SCHEMAS[1]) is not properly configured. DD tables might not be found.
2025-06-18 15:23:51,503 - tools.db_tools - WARNING - No specific metadata schema configured, attempting to use 'dd_tables' directly.
2025-06-18 15:23:51,503 - tools.db_tools - INFO - Tool: get_data_dictionary_tables - Querying Identifier('dd_tables').
2025-06-18 15:23:51,505 - tools.db_tools - ERROR - Tool: Error in get_data_dictionary_tables querying Identifier('dd_tables'): relation "dd_tables" does not exist
LINE 1: ...ECT "Table", "Priority", "Table Description" FROM "dd_tables...
                                                             ^
Traceback (most recent call last):
  File "/Users/dristipande/Desktop/walmart/tools/db_tools.py", line 277, in get_data_dictionary_tables
    cursor.execute(query)
    ~~~~~~~~~~~~~~^^^^^^^
  File "/Users/dristipande/Desktop/walmart/venv/lib/python3.13/site-packages/psycopg2/extras.py", line 236, in execute
    return super().execute(query, vars)
           ~~~~~~~~~~~~~~~^^^^^^^^^^^^^
psycopg2.errors.UndefinedTable: relation "dd_tables" does not exist
LINE 1: ...ECT "Table", "Priority", "Table Description" FROM "dd_tables...
                                                             ^

[33mUserProxy[0m (to SchemaAnalyst):

[32m***** Response from calling tool (call_ukDRXVruqdmXOfrbmMt8h8AX) *****[0m
[{'error': 'Failed to retrieve from Identifier(\'dd_tables\'): relation "dd_tables" does not exist\nLINE 1: ...ECT "Table", "Priority", "Table Description" FROM "dd_tables...\n                                                             ^\n'}]
[32m**********************************************************************[0m

--------------------------------------------------------------------------------
[31m
>>>>>>>> USING AUTO REPLY...[0m
2025-06-18 15:23:52,221 - httpx - INFO - HTTP Request: POST https://api.openai.com/v1/chat/completions "HTTP/1.1 200 OK"
[33mSchemaAnalyst[0m (to UserProxy):

[32m***** Suggested tool call (call_VLvG5LXjSRrA10XHUzsXluVY): get_all_db_objects *****[0m
Arguments: 
{}
[32m***********************************************************************************[0m

--------------------------------------------------------------------------------
[35m
>>>>>>>> EXECUTING FUNCTION get_all_db_objects...
Call ID: call_VLvG5LXjSRrA10XHUzsXluVY
Input arguments: {}[0m
[33mUserProxy[0m (to SchemaAnalyst):

[32m***** Response from calling tool (call_VLvG5LXjSRrA10XHUzsXluVY) *****[0m
{'tables': [{'schema': 'walmart_schema', 'name': 'calendar', 'full_name': 'walmart_schema.calendar'}, {'schema': 'walmart_schema', 'name': 'sales', 'full_name': 'walmart_schema.sales'}, {'schema': 'walmart_schema', 'name': 'sell_prices', 'full_name': 'walmart_schema.sell_prices'}], 'views': [], 'materialized_views': []}
[32m**********************************************************************[0m

--------------------------------------------------------------------------------
[31m
>>>>>>>> USING AUTO REPLY...[0m
2025-06-18 15:23:52,816 - httpx - INFO - HTTP Request: POST https://api.openai.com/v1/chat/completions "HTTP/1.1 200 OK"
[33mSchemaAnalyst[0m (to UserProxy):

[32m***** Suggested tool call (call_qYHUq0UH7Iccqh3CZM6x8mXz): get_all_db_objects *****[0m
Arguments: 
{}
[32m***********************************************************************************[0m

--------------------------------------------------------------------------------
[31m
>>>>>>>> TERMINATING RUN (9ba1ffc0-9bd5-4386-bd9a-bd5454796b91): Maximum turns (3) reached[0m
2025-06-18 15:23:52,819 - core.agent_manager_sequential - ERROR - Failed to parse JSON list with key 'tables': 'NoneType' object has no attribute 'find'. Content was: 'None'
2025-06-18 15:23:52,819 - core.agent_manager_sequential - ERROR - Error in orchestration workflow: Orchestrator could not parse a required response for key: tables
Traceback (most recent call last):
  File "/Users/dristipande/Desktop/walmart/core/agent_manager_sequential.py", line 218, in _parse_json_list
    json_str = self._extract_json_from_string(last_message)
  File "/Users/dristipande/Desktop/walmart/core/agent_manager_sequential.py", line 197, in _extract_json_from_string
    start_brace = text.find('{')
                  ^^^^^^^^^
AttributeError: 'NoneType' object has no attribute 'find'

During handling of the above exception, another exception occurred:

Traceback (most recent call last):
  File "/Users/dristipande/Desktop/walmart/core/agent_manager_sequential.py", line 49, in _orchestrate_workflow
    selected_tables = self._parse_json_list(chat_res_1, 'tables')
  File "/Users/dristipande/Desktop/walmart/core/agent_manager_sequential.py", line 223, in _parse_json_list
    raise ValueError(f"Orchestrator could not parse a required response for key: {key}")
ValueError: Orchestrator could not parse a required response for key: tables
2025-06-18 15:23:52,822 - core.agent_manager_sequential - INFO - AgentManager.process_query finished for query: 'Which category had the lowest average sales?'
2025-06-18 15:23:52,822 - api.routes.agent_sequential - INFO - API Endpoint: agent_manager.process_query returned.
2025-06-18 15:23:52,823 - main_sequential - INFO - --- FINISHED CAPTURING OUTPUT for req_id ea52aa6a. File: full_request_logs/req_full_output_20250618_152350_433842_ea52aa6a.log ---
--- STDOUT/STDERR REDIRECTION ENDED (ReqID: ea52aa6a, Time: 2025-06-18 15:23:52.823217) ---
