2025-06-19 11:26:43,520 - main_sequential - INFO - --- CAPTURING ALL OUTPUT for req_id 972e1dd1 to: full_request_logs/req_full_output_20250619_112643_518715_972e1dd1.log ---
2025-06-19 11:26:43,525 - api.routes.agent_sequential - INFO - Console: Received query in agent.py endpoint: Which category had the highest average sales in March 2013?
2025-06-19 11:26:43,525 - core.agent_manager_sequential - INFO - AgentManager.process_query received query: 'Which category had the highest average sales in March 2013?'
2025-06-19 11:26:43,525 - core.agent_manager_sequential - INFO - --- XIYAN-SQL ORCHESTRATED WORKFLOW START ---
2025-06-19 11:26:43,614 - core.agents_sequential - INFO - METADATA_AVAILABLE is True. Registering data dictionary tools.
2025-06-19 11:26:43,639 - core.agent_manager_sequential - INFO - [Orchestrator] STAGE 1: Schema Linking
--- STDOUT/STDERR REDIRECTION ACTIVE (ReqID: 972e1dd1, Time: 2025-06-19 11:26:43.521543) ---
created new sequential agents
[33mUserProxy[0m (to SchemaAnalyst):

User Question: 'Which category had the highest average sales in March 2013?'

--------------------------------------------------------------------------------
[31m
>>>>>>>> USING AUTO REPLY...[0m
2025-06-19 11:26:44,370 - httpx - INFO - HTTP Request: POST https://api.openai.com/v1/chat/completions "HTTP/1.1 200 OK"
[33mSchemaAnalyst[0m (to UserProxy):

[32m***** Suggested tool call (call_iYcw02sgGAXFijgvfAJnCpph): get_data_dictionary_tables *****[0m
Arguments: 
{}
[32m*******************************************************************************************[0m

--------------------------------------------------------------------------------
[35m
>>>>>>>> EXECUTING FUNCTION get_data_dictionary_tables...
Call ID: call_iYcw02sgGAXFijgvfAJnCpph
Input arguments: {}[0m
2025-06-19 11:26:44,424 - tools.db_tools - WARNING - METADATA SCHEMA (DB_SCHEMAS[1]) is not properly configured. DD tables might not be found.
2025-06-19 11:26:44,425 - tools.db_tools - WARNING - No specific metadata schema configured, attempting to use 'dd_tables' directly.
2025-06-19 11:26:44,425 - tools.db_tools - INFO - Tool: get_data_dictionary_tables - Querying Identifier('dd_tables').
2025-06-19 11:26:44,445 - tools.db_tools - ERROR - Tool: Error in get_data_dictionary_tables querying Identifier('dd_tables'): relation "dd_tables" does not exist
LINE 1: ...ECT "Table", "Priority", "Table Description" FROM "dd_tables...
                                                             ^
Traceback (most recent call last):
  File "/Users/dristipande/Desktop/walmart/tools/db_tools.py", line 277, in get_data_dictionary_tables
    cursor.execute(query)
    ~~~~~~~~~~~~~~^^^^^^^
  File "/Users/dristipande/Desktop/walmart/venv/lib/python3.13/site-packages/psycopg2/extras.py", line 236, in execute
    return super().execute(query, vars)
           ~~~~~~~~~~~~~~~^^^^^^^^^^^^^
psycopg2.errors.UndefinedTable: relation "dd_tables" does not exist
LINE 1: ...ECT "Table", "Priority", "Table Description" FROM "dd_tables...
                                                             ^

[33mUserProxy[0m (to SchemaAnalyst):

[32m***** Response from calling tool (call_iYcw02sgGAXFijgvfAJnCpph) *****[0m
[{'error': 'Failed to retrieve from Identifier(\'dd_tables\'): relation "dd_tables" does not exist\nLINE 1: ...ECT "Table", "Priority", "Table Description" FROM "dd_tables...\n                                                             ^\n'}]
[32m**********************************************************************[0m

--------------------------------------------------------------------------------
[31m
>>>>>>>> USING AUTO REPLY...[0m
2025-06-19 11:26:44,972 - httpx - INFO - HTTP Request: POST https://api.openai.com/v1/chat/completions "HTTP/1.1 200 OK"
[33mSchemaAnalyst[0m (to UserProxy):

[32m***** Suggested tool call (call_2Lp1tbY869VEOjcOI4MuwFpQ): get_all_db_objects *****[0m
Arguments: 
{}
[32m***********************************************************************************[0m

--------------------------------------------------------------------------------
[35m
>>>>>>>> EXECUTING FUNCTION get_all_db_objects...
Call ID: call_2Lp1tbY869VEOjcOI4MuwFpQ
Input arguments: {}[0m
[33mUserProxy[0m (to SchemaAnalyst):

[32m***** Response from calling tool (call_2Lp1tbY869VEOjcOI4MuwFpQ) *****[0m
{'tables': [{'schema': 'walmart_schema', 'name': 'calendar', 'full_name': 'walmart_schema.calendar'}, {'schema': 'walmart_schema', 'name': 'sales', 'full_name': 'walmart_schema.sales'}, {'schema': 'walmart_schema', 'name': 'sell_prices', 'full_name': 'walmart_schema.sell_prices'}], 'views': [], 'materialized_views': []}
[32m**********************************************************************[0m

--------------------------------------------------------------------------------
[31m
>>>>>>>> USING AUTO REPLY...[0m
2025-06-19 11:26:45,947 - httpx - INFO - HTTP Request: POST https://api.openai.com/v1/chat/completions "HTTP/1.1 200 OK"
[33mSchemaAnalyst[0m (to UserProxy):

[32m***** Suggested tool call (call_afrXdfC4IeDXuVhVYrSjH3gh): get_all_db_objects *****[0m
Arguments: 
{}
[32m***********************************************************************************[0m

--------------------------------------------------------------------------------
[31m
>>>>>>>> TERMINATING RUN (20bb8650-1a28-4f7a-8953-3570f6890f54): Maximum turns (3) reached[0m
2025-06-19 11:26:45,953 - core.agent_manager_sequential - ERROR - Failed to parse JSON list with key 'tables': 'NoneType' object has no attribute 'find'. Content was: 'None'
2025-06-19 11:26:45,953 - core.agent_manager_sequential - ERROR - Error in orchestration workflow: Orchestrator could not parse a required response for key: tables
Traceback (most recent call last):
  File "/Users/dristipande/Desktop/walmart/core/agent_manager_sequential.py", line 223, in _parse_json_list
    json_str = self._extract_json_from_string(last_message)
  File "/Users/dristipande/Desktop/walmart/core/agent_manager_sequential.py", line 202, in _extract_json_from_string
    start_brace = text.find('{')
                  ^^^^^^^^^
AttributeError: 'NoneType' object has no attribute 'find'

During handling of the above exception, another exception occurred:

Traceback (most recent call last):
  File "/Users/dristipande/Desktop/walmart/core/agent_manager_sequential.py", line 49, in _orchestrate_workflow
    selected_tables = self._parse_json_list(chat_res_1, 'tables')
  File "/Users/dristipande/Desktop/walmart/core/agent_manager_sequential.py", line 228, in _parse_json_list
    raise ValueError(f"Orchestrator could not parse a required response for key: {key}")
ValueError: Orchestrator could not parse a required response for key: tables
2025-06-19 11:26:45,956 - core.agent_manager_sequential - INFO - AgentManager.process_query finished for query: 'Which category had the highest average sales in March 2013?'
2025-06-19 11:26:45,956 - api.routes.agent_sequential - INFO - API Endpoint: agent_manager.process_query returned.
2025-06-19 11:26:45,957 - main_sequential - INFO - --- FINISHED CAPTURING OUTPUT for req_id 972e1dd1. File: full_request_logs/req_full_output_20250619_112643_518715_972e1dd1.log ---
--- STDOUT/STDERR REDIRECTION ENDED (ReqID: 972e1dd1, Time: 2025-06-19 11:26:45.957171) ---
